<?xml version="1.0" ?>
<robot name="model5" xmlns:xacro="http://www.ros.org/wiki/xacro">

<xacro:include filename="$(find model5_description)/urdf/materials.xacro" />
<xacro:include filename="$(find model5_description)/urdf/model5.trans" />
<xacro:include filename="$(find model5_description)/urdf/model5.gazebo" />
<link name="base_link">
  <inertial>
    <origin rpy="0 0 0" xyz="0 0 0.1009046148047008"/>
    <mass value="2.993362458147853"/>
    <inertia ixx="0.018002" ixy="-0.0" ixz="0.0" iyy="0.018465" iyz="-0.0" izz="0.010619"/>
  </inertial>
  <visual>
    <origin rpy="0 0 0" xyz="0 0 0"/>
    <geometry>
      <mesh filename="package://model5_description/meshes/base_link.stl" scale="0.001 0.001 0.001"/>
    </geometry>
    <material name="silver"/>
  </visual>
  <collision>
    <origin rpy="0 0 0" xyz="0 0 0"/>
    <geometry>
      <mesh filename="package://model5_description/meshes/base_link.stl" scale="0.001 0.001 0.001"/>
    </geometry>
  </collision>
</link>

<link name="right_wheel_1">
  <inertial>
    <origin rpy="0 0 0" xyz="-0.012499999999999997 0 0"/>
    <mass value="0.36730470107572427"/>
    <inertia ixx="0.00011" ixy="0.0" ixz="0.0" iyy="7.3e-05" iyz="0.0" izz="7.3e-05"/>
  </inertial>
  <visual>
    <origin rpy="0 0 0" xyz="0.07 -0.0 -0.02825"/>
    <geometry>
      <mesh filename="package://model5_description/meshes/right_wheel_1.stl" scale="0.001 0.001 0.001"/>
    </geometry>
    <material name="silver"/>
  </visual>
  <collision>
    <origin rpy="0 0 0" xyz="0.07 -0.0 -0.02825"/>
    <geometry>
      <mesh filename="package://model5_description/meshes/right_wheel_1.stl" scale="0.001 0.001 0.001"/>
    </geometry>
  </collision>
</link>

<link name="left_wheel_1">
  <inertial>
    <origin rpy="0 0 0" xyz="0.012499999999999886 0 0"/>
    <mass value="0.3673047010757242"/>
    <inertia ixx="0.00011" ixy="-0.0" ixz="0.0" iyy="7.3e-05" iyz="-0.0" izz="7.3e-05"/>
  </inertial>
  <visual>
    <origin rpy="0 0 0" xyz="-0.07 -0.0 -0.02825"/>
    <geometry>
      <mesh filename="package://model5_description/meshes/left_wheel_1.stl" scale="0.001 0.001 0.001"/>
    </geometry>
    <material name="silver"/>
  </visual>
  <collision>
    <origin rpy="0 0 0" xyz="-0.07 -0.0 -0.02825"/>
    <geometry>
      <mesh filename="package://model5_description/meshes/left_wheel_1.stl" scale="0.001 0.001 0.001"/>
    </geometry>
  </collision>
</link>

<joint name="Rev4" type="continuous">
  <origin rpy="0 0 0" xyz="-0.07 0.0 0.02825"/>
  <parent link="base_link"/>
  <child link="right_wheel_1"/>
  <axis xyz="-1.0 0.0 0.0"/>
</joint>

<joint name="Rev5" type="continuous">
  <origin rpy="0 0 0" xyz="0.07 0.0 0.02825"/>
  <parent link="base_link"/>
  <child link="left_wheel_1"/>
  <axis xyz="1.0 0.0 0.0"/>
</joint>





<link name="imu_link">
    <inertial>
        <origin xyz="0 0 0" rpy="0 0 0"/>
        <mass value="0.01"/>
        <inertia ixx="0.1" ixy="-0.1" ixz="0.0" iyy="0.0" iyz="0.0" izz="0.0"/>
    </inertial>

    <visual>
        <origin xyz="0 0 0" rpy="0 0 0" />
        <geometry>
        <cylinder radius="0.005" length="0.005"/>
        </geometry>
        <material name="silver"/>
    </visual>

    <collision>
        <origin xyz="0 0 0" rpy="0 0 0"/>
        <geometry>
        <cylinder radius="0.005" length="0.05"/>
        </geometry>
    </collision>
  </link>

  <joint name="joint_sensor_laser" type="fixed">
    <origin xyz="0.01 0.01 0.192" rpy="0 0 0"/>
    <parent link="base_link"/>
    <child link="imu_link"/>
  </joint>

</robot>
